Workbook
Name Slicer_Month: #N/A
Name Slicer_Product: #N/A
Name Slicer_Region: #N/A

Sheet Raw Data
A1: Date | B1: Region | C1: Product | D1: Sales | E1: Cost
A2: 45292 | B2: North | C2: B | D2: 810 | E2: 53
A3: 45293 | B3: West | C3: C | D3: 374 | E3: 276
A4: 45294 | B4: South | C4: D | D4: 960 | E4: 730
A5: 45295 | B5: North | C5: C | D5: 143 | E5: 494
A6: 45296 | B6: West | C6: C | D6: 183 | E6: 467
A7: 45297 | B7: West | C7: D | D7: 533 | E7: 334
A8: 45298 | B8: West | C8: B | D8: 909 | E8: 76
A9: 45299 | B9: West | C9: A | D9: 193 | E9: 786
A10: 45300 | B10: South | C10: A | D10: 274 | E10: 298
A11: 45301 | B11: West | C11: A | D11: 505 | E11: 415
A12: 45302 | B12: South | C12: D | D12: 301 | E12: 251
A13: 45303 | B13: East | C13: D | D13: 957 | E13: 487
... A59: 45349 | B59: East | C59: D | D59: 327 | E59: 795
A60: 45350 | B60: North | C60: A | E60: 182
A61: 45351 | B61: West | C61: A | D61: 695 | E61: 491
A62: 45352 | B62: West | C62: D | D62: 747 | E62: 143
A63: 45353 | B63: East | C63: B | D63: 673 | E63: 397
A64: 45354 | B64: West | C64: C | D64: 753 | E64: 451
A65: 45355 | B65: East | C65: A | D65: 617 | E65: 469
A66: 45356 | B66: West | C66: C | D66: 356 | E66: 756
A67: 45357 | B67: North | C67: D | D67: 236 | E67: 454
A68: 45358 | B68: East | C68: D | D68: 307 | E68: 235
A69: 45359 | B69: North | C69: C | D69: 563 | E69: 425
A70: 45360 | B70: North | C70: D | D70: 239 | E70: 726
A71: 45361 | B71: North | C71: B | D71: 104 | E71: 752
A72: 45362 | B72: South | C72: B | D72: 523 | E72: 566
... A98: 45388 | B98: East | C98: C | D98: 194 | E98: 568
A99: 45389 | B99: West | C99: C | E99: 735
A100: 45390 | B100: South | C100: D | D100: 436 | E100: 295
A101: 45391 | B101: North | C101: B | D101: 766 | E101: 464
A102: 45392 | B102: South | C102: B | D102: 736 | E102: 577
A103: 45393 | B103: East | C103: A | D103: 263 | E103: 219
A104: 45394 | B104: North | C104: D | D104: 670 | E104: 216
A105: 45395 | B105: West | C105: A | D105: 206 | E105: 359
A106: 45396 | B106: North | C106: C | D106: 301 | E106: 644
A107: 45397 | B107: East | C107: D | D107: 400 | E107: 441
A108: 45398 | B108: North | C108: D | D108: 881 | E108: 270
A109: 45399 | B109: West | C109: B | D109: 989 | E109: 731
A110: 45400 | B110: West | C110: D | D110: 938 | E110: 164
...

Sheet cleaned
A1: Date | B1: Region | C1: Product | D1: Sales | E1: Cost | F1: Month | G1: Year | H1: Profit
A2: 45292 | B2: North | C2: B | D2: 810 | E2: 53 | F2: January | G2: 2024 | H2: =D2-E2 -> 757
A3: 45293 | B3: West | C3: C | D3: 374 | E3: 276 | F3: January | G3: 2024 | H3: =D3-E3 -> 98
A4: 45294 | B4: South | C4: D | D4: 960 | E4: 730 | F4: January | G4: 2024 | H4: =D4-E4 -> 230
A5: 45295 | B5: North | C5: C | D5: 143 | E5: 494 | F5: January | G5: 2024 | H5: =D5-E5 -> -351
A6: 45296 | B6: West | C6: C | D6: 183 | E6: 467 | F6: January | G6: 2024 | H6: =D6-E6 -> -284
A7: 45297 | B7: West | C7: D | D7: 533 | E7: 334 | F7: January | G7: 2024 | H7: =D7-E7 -> 199
A8: 45298 | B8: West | C8: B | D8: 909 | E8: 76 | F8: January | G8: 2024 | H8: =D8-E8 -> 833
A9: 45299 | B9: West | C9: A | D9: 193 | E9: 786 | F9: January | G9: 2024 | H9: =D9-E9 -> -593
A10: 45300 | B10: South | C10: A | D10: 274 | E10: 298 | F10: January | G10: 2024 | H10: =D10-E10 -> -24
A11: 45301 | B11: West | C11: A | D11: 505 | E11: 415 | F11: January | G11: 2024 | H11: =D11-E11 -> 90
A12: 45302 | B12: South | C12: D | D12: 301 | E12: 251 | F12: January | G12: 2024 | H12: =D12-E12 -> 50
A13: 45303 | B13: East | C13: D | D13: 957 | E13: 487 | F13: January | G13: 2024 | H13: =D13-E13 -> 470
... A206: 45386 | B206: West | C206: A | D206: 153 | E206: 377 | F206: April | G206: 2024 | H206: =D206-E206 -> -224

Sheet Pivot_Summary
A1: Row Labels | B1: Sum of Sales | D1: Row Labels | E1: Sum of Sales | H1: Row Labels | I1: Sum of Sales
A2: East | B2: 25846 | D2: January | E2: 17161 | H2: A | I2: 25274
A3: North | B3: 23869 | D3: February | E3: 14341 | H3: B | I3: 30551
A4: South | B4: 23908 | D4: March | E4: 18685 | H4: C | I4: 21392
A5: West | B5: 33724 | D5: April | E5: 17760 | H5: D | I5: 30130
A6: Grand Total | B6: 107347 | D6: May | E6: 15620 | H6: Grand Total | I6: 107347
D7: June | E7: 14275
D8: July | E8: 9505
D9: Grand Total | E9: 107347

Sheet KPI
A1: Metrics | B1: Values
A2: Total sales | B2: =SUM(cleaned!D170:D206) -> 17408
A3: Total cost | B3: =SUM(cleaned!E170:E206) -> 16767
A4: Total profit | B4: =SUM(cleaned!H170:H206) -> 641
A5: Profit Margin | B5: =SUM(SUM(cleaned!H170:H206)/SUM(cleaned!D170:D206)) -> 0.036822151
A6: Number of Transactions | B6: =COUNT(cleaned!A:A) -> 205

Sheet Reconsilation
A1: Metric | B1: Raw Data | C1: Clean data | D1: Difference
A2: Total sales | B2: =SUM('Raw Data'!D2:D206) -> 107347 | C2: =SUM(query[Sales]) -> 107347 | D2: 0
A3: Total cost | B3: =SUM('Raw Data'!E2:E206) -> 92259 | C3: =SUM(query[Cost]) -> 92259 | D3: 0
A4: Record count | B4: =COUNT('Raw Data'!A:A) -> 205 | C4: =COUNT(cleaned!A:A) -> 205 | D4: 0

Sheet query_exception_log
A1: Date | B1: Region | C1: Product | D1: Sales | E1: Cost | F1: Month | G1: Year | H1: Issue type
A2: 45350 | B2: North | C2: A | E2: 182 | F2: February | G2: 2024 | H2: Missing sales
A3: 45389 | B3: West | C3: C | E3: 735 | F3: April | G3: 2024 | H3: Missing sales
A4: 45427 | B4: South | C4: B | E4: 759 | F4: May | G4: 2024 | H4: Missing sales
A5: 45438 | B5: West | C5: A | E5: 654 | F5: May | G5: 2024 | H5: Missing sales
A6: 45444 | B6: East | C6: B | E6: 150 | F6: June | G6: 2024 | H6: Missing sales
A7: 45456 | B7: West | C7: A | E7: 479 | F7: June | G7: 2024 | H7: Missing sales
A8: 45460 | B8: West | C8: B | E8: 169 | F8: June | G8: 2024 | H8: Missing sales
A9: 45469 | B9: North | C9: B | E9: 634 | F9: June | G9: 2024 | H9: Missing sales
A10: 45475 | B10: East | C10: C | E10: 501 | F10: July | G10: 2024 | H10: Missing sales
A11: 45338 | B11: West | C11: B | D11: -100 | E11: 685 | F11: February | G11: 2024 | H11: Negative sales
A12: 45373 | B12: West | C12: D | D12: -100 | E12: 424 | F12: March | G12: 2024 | H12: Negative sales
A13: 45419 | B13: South | C13: D | D13: -100 | E13: 188 | F13: May | G13: 2024 | H13: Negative sales
A14: 45453 | B14: East | C14: D | D14: -100 | E14: 442 | F14: June | G14: 2024 | H14: Negative sales
A15: 45473 | B15: North | C15: A | D15: -100 | E15: 749 | F15: June | G15: 2024 | H15: Negative sales
A16: 45300 | B16: South | C16: A | D16: 274 | E16: 298 | F16: January | G16: 2024 | H16: Duplicates
A17: 45303 | B17: East | C17: D | D17: 957 | E17: 487 | F17: January | G17: 2024 | H17: Duplicates
A18: 45361 | B18: North | C18: B | D18: 104 | E18: 752 | F18: March | G18: 2024 | H18: Duplicates
A19: 45386 | B19: West | C19: A | D19: 153 | E19: 377 | F19: April | G19: 2024 | H19: Duplicates
A20: 45433 | B20: West | C20: A | D20: 797 | E20: 221 | F20: May | G20: 2024 | H20: Duplicates
A21: 45303 | B21: East | C21: D | D21: 957 | E21: 487 | F21: January | G21: 2024 | H21: Duplicates
A22: 45433 | B22: West | C22: A | D22: 797 | E22: 221 | F22: May | G22: 2024 | H22: Duplicates
... A25: 45386 | B25: West | C25: A | D25: 153 | E25: 377 | F25: April | G25: 2024 | H25: Duplicates

Sheet query_null_sales
A1: Date | B1: Region | C1: Product | D1: Sales | E1: Cost | F1: Month | G1: Year | H1: Issue type
A2: 45350 | B2: North | C2: A | E2: 182 | F2: February | G2: 2024 | H2: Missing sales
A3: 45389 | B3: West | C3: C | E3: 735 | F3: April | G3: 2024 | H3: Missing sales
A4: 45427 | B4: South | C4: B | E4: 759 | F4: May | G4: 2024 | H4: Missing sales
A5: 45438 | B5: West | C5: A | E5: 654 | F5: May | G5: 2024 | H5: Missing sales
A6: 45444 | B6: East | C6: B | E6: 150 | F6: June | G6: 2024 | H6: Missing sales
A7: 45456 | B7: West | C7: A | E7: 479 | F7: June | G7: 2024 | H7: Missing sales
A8: 45460 | B8: West | C8: B | E8: 169 | F8: June | G8: 2024 | H8: Missing sales
A9: 45469 | B9: North | C9: B | E9: 634 | F9: June | G9: 2024 | H9: Missing sales
A10: 45475 | B10: East | C10: C | E10: 501 | F10: July | G10: 2024 | H10: Missing sales

Sheet query _negative_sales
A1: Date | B1: Region | C1: Product | D1: Sales | E1: Cost | F1: Month | G1: Year | H1: Issue type
A2: 45338 | B2: West | C2: B | D2: -100 | E2: 685 | F2: February | G2: 2024 | H2: Negative sales
A3: 45373 | B3: West | C3: D | D3: -100 | E3: 424 | F3: March | G3: 2024 | H3: Negative sales
A4: 45419 | B4: South | C4: D | D4: -100 | E4: 188 | F4: May | G4: 2024 | H4: Negative sales
A5: 45453 | B5: East | C5: D | D5: -100 | E5: 442 | F5: June | G5: 2024 | H5: Negative sales
A6: 45473 | B6: North | C6: A | D6: -100 | E6: 749 | F6: June | G6: 2024 | H6: Negative sales

Sheet query_duplicates
A1: Date | B1: Region | C1: Product | D1: Sales | E1: Cost | F1: Month | G1: Year | H1: Issue type
A2: 45300 | B2: South | C2: A | D2: 274 | E2: 298 | F2: January | G2: 2024 | H2: Duplicates
A3: 45303 | B3: East | C3: D | D3: 957 | E3: 487 | F3: January | G3: 2024 | H3: Duplicates
A4: 45361 | B4: North | C4: B | D4: 104 | E4: 752 | F4: March | G4: 2024 | H4: Duplicates
A5: 45386 | B5: West | C5: A | D5: 153 | E5: 377 | F5: April | G5: 2024 | H5: Duplicates
A6: 45433 | B6: West | C6: A | D6: 797 | E6: 221 | F6: May | G6: 2024 | H6: Duplicates
A7: 45303 | B7: East | C7: D | D7: 957 | E7: 487 | F7: January | G7: 2024 | H7: Duplicates
A8: 45433 | B8: West | C8: A | D8: 797 | E8: 221 | F8: May | G8: 2024 | H8: Duplicates
A9: 45300 | B9: South | C9: A | D9: 274 | E9: 298 | F9: January | G9: 2024 | H9: Duplicates
A10: 45361 | B10: North | C10: B | D10: 104 | E10: 752 | F10: March | G10: 2024 | H10: Duplicates
A11: 45386 | B11: West | C11: A | D11: 153 | E11: 377 | F11: April | G11: 2024 | H11: Duplicates

Sheet Data_Quality
F9: Metric | G9: Values
F10: Total Records | G10: =COUNTA(cleaned!A:A) -> 206
F11: Clean Records | G11: =ROWS(query[Date]) -> 205
F12: Null sales | G12: =COUNTBLANK('Raw Data'!D2:D206) -> 9
F13: Negative sales | G13: =COUNTIF('Raw Data'!D:D, "<0") -> 5
F14: Duplicates | G14: =COUNTIF(query_exception_log!H:H,"Duplicates") -> 10
F15: % Clean data | G15: =G11/G10 -> 0.99514563

Sheet Instructions
A1: Reporting automation
A3: Goal:
A4: To allow easy, one-click refresh of the report using updated data without manual changes.
A6: step 1 : Update source data
A7: Replace the old data file with the new one or Add new file to the source folder Note: columns should be same
A10: step 2 : open the workbook
A11: Open the Excel reporting file
A13: step 3 : refresh all data
A14: Data -> Refresh ALL 0r ctrl+alt+F5
A17: step 4 : check outputs
A18: cleaned,pivot_summary,KPI,Reconsilation,query_exception_log
A22: Notes:
... A26: Only update raw data source, Ensure no extra or missing columns
